<?xml version="1.0"?>
<robot name="pleurobot" xmlns:xacro="http://www.ros.org/wiki/xacro">

  <link name="base_link"/>
    <joint name="base_link_fixedjoint" type="fixed">
      <parent link="base_link"/>
      <child link="link1"/>
      <origin xyz="0 0 0.16" rpy="3.1416 0 0 "/>
      <axis xyz="0 0 0"/>
  	</joint>

  <link name="link1">
    <visual>
    <origin xyz="-0.5 0.612 0.515" rpy="3.1416 0 -1.5708 "/>
      <geometry>
        <mesh filename="package://pleurobot_ros_pkg/meshes/link1.STL" scale=".0015 .0015 .0015"/>
      </geometry>
    </visual>
    <collision>
    <origin xyz="-0.5 0.612 0.515" rpy="3.1416 0 -1.5708 "/>
      <geometry>
        <mesh filename="package://pleurobot_ros_pkg/meshes/link1.STL" scale=".0015 .0015 .0015"/>
      </geometry>
    </collision>
    <inertial>
      <mass value="0.85" />
      <origin xyz="0 0 0" rpy="0 0 0"/>
      <inertia ixx="0.025492" ixy="0" ixz="0" iyy="0.032502" iyz="-3.26672e-18" izz="0.01779"/>
    </inertial>
  </link>

  <joint name="j2" type="revolute">
    <parent link="link1"/>
    <child  link="link2"/>
    <origin xyz="-0.095 -0.0015 0.001" rpy="0 0 0 "/>
    <axis   xyz="0 0 1"/>
    <limit lower="-0.6981" upper="0.6981" effort="19.7336" velocity="3.2" />    
  </joint>

  <link name="link2">
    <visual>
    <origin xyz="-0.405 0.6135 0.516" rpy="3.1416 0 -1.5708 "/>
      <geometry>
        <mesh filename="package://pleurobot_ros_pkg/meshes/link2.STL" scale=".0015 .0015 .0015"/>
      </geometry>
    </visual>
    <collision>
    <origin xyz="-0.405 0.6135 0.516" rpy="3.1416 0 -1.5708 "/>
      <geometry>
        <mesh filename="package://pleurobot_ros_pkg/meshes/link2.STL" scale=".0015 .0015 .0015"/>
      </geometry>
    </collision>
    <inertial>
      <mass value="0.3619" />
      <origin xyz="0 0 0" rpy="0 0 0"/>
      <inertia ixx="0.025492" ixy="0" ixz="0" iyy="0.032502" iyz="-3.26672e-18" izz="0.01779"/>
    </inertial>
  </link>

  <joint name="j3" type="revolute">
    <parent link="link2"/>
    <child  link="link3"/>
    <origin xyz="-0.17 0 0" rpy="0 0 0 "/>
    <axis   xyz="0 0 1"/>
    <limit lower="-0.6981" upper="0.6981" effort="19.7336" velocity="3.2" />     
  </joint>

  <link name="link3">
    <visual>
      <origin xyz="-0.235 0.6135 0.515" rpy="3.1416 0 -1.5708 "/>
      <geometry>
        <mesh filename="package://pleurobot_ros_pkg/meshes/link3.STL" scale=".0015 .0015 .0015"/>
      </geometry>
    </visual>
    <collision>
      <origin xyz="-0.235 0.6135 0.515" rpy="3.1416 0 -1.5708 "/>
      <geometry>
        <mesh filename="package://pleurobot_ros_pkg/meshes/link3.STL" scale=".0015 .0015 .0015"/>
      </geometry>
    </collision>
    <inertial>
      <mass value="0.3429" />
      <origin xyz="0 0 0" rpy="0 0 0"/>
      <inertia ixx="0.025492" ixy="0" ixz="0" iyy="0.032502" iyz="-3.26672e-18" izz="0.01779"/>
    </inertial>
  </link>

  <joint name="j4" type="revolute">
    <parent link="link3"/>
    <child  link="link4"/>
    <origin xyz="-0.145 0 -0.0001" rpy="0 0 0 "/>
    <axis   xyz="0 0 1"/>
    <limit lower="-0.6981" upper="0.6981" effort="19.7336" velocity="3.2" />    
  </joint>

  <link name="link4">
    <visual>
      <origin xyz="-0.09 0.6135 0.515" rpy="3.1416 0 -1.5708 "/>
      <geometry>
        <mesh filename="package://pleurobot_ros_pkg/meshes/link4.STL" scale=".0015 .0015 .0015"/>
      </geometry>
    </visual>
    <collision>
      <origin xyz="-0.09 0.6135 0.515" rpy="3.1416 0 -1.5708 "/>
      <geometry>
        <mesh filename="package://pleurobot_ros_pkg/meshes/link4.STL" scale=".0015 .0015 .0015"/>
      </geometry>
    </collision>
    <inertial>
      <mass value="0.3329" />
      <origin xyz="0 0 0" rpy="0 0 0"/>
      <inertia ixx="0.025492" ixy="0" ixz="0" iyy="0.032502" iyz="-3.26672e-18" izz="0.01779"/>
    </inertial>
  </link>

  <joint name="j5" type="revolute">
    <parent link="link4"/>
    <child  link="link5"/>
    <origin xyz="-0.13 0 0" rpy="0 0 0 "/>
    <axis   xyz="0 0 1"/>
    <limit lower="-0.6981" upper="0.6981" effort="19.7336" velocity="3.2" />     
  </joint>

  <link name="link5">
    <visual>
      <origin xyz="0.04 0.6135 0.515" rpy="3.1416 0 -1.5708 "/>
      <geometry>
        <mesh filename="package://pleurobot_ros_pkg/meshes/link5.STL" scale=".0015 .0015 .0015"/>
      </geometry>
    </visual>
    <collision>
      <origin xyz="0.04 0.6135 0.515" rpy="3.1416 0 -1.5708 "/>
      <geometry>
        <mesh filename="package://pleurobot_ros_pkg/meshes/link5.STL" scale=".0015 .0015 .0015"/>
      </geometry>
    </collision>
    <inertial>
      <mass value="0.3319" />
      <origin xyz="0 0 0" rpy="0 0 0"/>
      <inertia ixx="0.025492" ixy="0" ixz="0" iyy="0.032502" iyz="-3.26672e-18" izz="0.01779"/>
    </inertial>
  </link>

</robot>
